<script>
    function a(num) {
        return new Promise((resolve,reject)=>{
            if(num>5){
                setTimeout(()=>resolve('resolved'),2000)
            }else {
                setTimeout(()=>reject('rejected'),2000)
            }
        })
    }
    // await命令后面的 Promise 对象如果变为reject状态，则reject的参数会被catch方法的回调函数接收到。
    // 任何一个await语句后面的 Promise 对象变为reject状态，那么整个async函数都会中断执行（相当于抛出错误）。
    async function b(num) {
        let n = await a(num);
        console.log(n)
        return n
        // if(n==="resolved") return n //不需要判断 能走到return表明 await 后面的promise对象是resolved状态
        // else throw 'rejected' //不需要 当await语句后面的 Promise 对象变为reject状态会自动抛出错误
    }

    b(6).then(val=>console.log('then:'+val)).catch(error=>console.log('catch:'+error)) 
    //resolved 
    //then:resolved
    b(5).then(val=>console.log('then:'+val)).catch(error=>console.log('catch:'+error)) 
    //catch:rejected
</script>